<?xml version="1.0" ?>
<!-- =================================================================================== -->
<!-- |    This document was autogenerated by xacro from ur5e.urdf.xacro              | -->
<!-- |    EDITING THIS FILE BY HAND IS NOT RECOMMENDED                                 | -->
<!-- =================================================================================== -->
<robot name="ur5e_robot">
  <!-- links -->
  <link name="base"/>
  <link name="base_link"/>
  <link name="base_link_inertia">
    <visual>
      <origin rpy="0 0 3.141592653589793" xyz="0 0 0"/>
      <geometry>
        <mesh filename="package://ur_description/meshes/ur5e/visual/base.dae"/>
      </geometry>
      <material name="LightGrey">
        <color rgba="0.7 0.7 0.7 1.0"/>
      </material>
    </visual>
    <collision>
      <origin rpy="0 0 3.141592653589793" xyz="0 0 0"/>
      <geometry>
        <mesh filename="package://ur_description/meshes/ur5e/collision/base.stl"/>
      </geometry>
    </collision>
    <inertial>
      <mass value="4.0"/>
      <origin rpy="0 0 0" xyz="0 0 0"/>
      <inertia ixx="0.00443333156" ixy="0.0" ixz="0.0" iyy="0.00443333156" iyz="0.0" izz="0.0072"/>
    </inertial>
  </link>
  <link name="shoulder_link">
    <visual>
      <origin rpy="0 0 3.141592653589793" xyz="0 0 0"/>
      <geometry>
        <mesh filename="package://ur_description/meshes/ur5e/visual/shoulder.dae"/>
      </geometry>
      <material name="LightGrey">
        <color rgba="0.7 0.7 0.7 1.0"/>
      </material>
    </visual>
    <collision>
      <origin rpy="0 0 3.141592653589793" xyz="0 0 0"/>
      <geometry>
        <mesh filename="package://ur_description/meshes/ur5e/collision/shoulder.stl"/>
      </geometry>
    </collision>
    <inertial>
      <mass value="3.7"/>
      <origin rpy="0 0 0" xyz="0 0 0"/>
      <inertia ixx="0.010267495893" ixy="0.0" ixz="0.0" iyy="0.010267495893" iyz="0.0" izz="0.00666"/>
    </inertial>
  </link>
  <link name="upper_arm_link">
    <visual>
      <origin rpy="0 0 3.141592653589793" xyz="0 0 0"/>
      <geometry>
        <mesh filename="package://ur_description/meshes/ur5e/visual/upperarm.dae"/>
      </geometry>
      <material name="LightGrey">
        <color rgba="0.7 0.7 0.7 1.0"/>
      </material>
    </visual>
    <collision>
      <origin rpy="0 0 3.141592653589793" xyz="0 0 0"/>
      <geometry>
        <mesh filename="package://ur_description/meshes/ur5e/collision/upperarm.stl"/>
      </geometry>
    </collision>
    <inertial>
      <mass value="8.393"/>
      <origin rpy="0 0 0" xyz="0 0 0.28"/>
      <inertia ixx="0.22689067591" ixy="0.0" ixz="0.0" iyy="0.22689067591" iyz="0.0" izz="0.0151074"/>
    </inertial>
  </link>
  <link name="forearm_link">
    <visual>
      <origin rpy="0 0 3.141592653589793" xyz="0 0 0"/>
      <geometry>
        <mesh filename="package://ur_description/meshes/ur5e/visual/forearm.dae"/>
      </geometry>
      <material name="LightGrey">
        <color rgba="0.7 0.7 0.7 1.0"/>
      </material>
    </visual>
    <collision>
      <origin rpy="0 0 3.141592653589793" xyz="0 0 0"/>
      <geometry>
        <mesh filename="package://ur_description/meshes/ur5e/collision/forearm.stl"/>
      </geometry>
    </collision>
    <inertial>
      <mass value="2.275"/>
      <origin rpy="0 0 0" xyz="0 0 0.25"/>
      <inertia ixx="0.049443313556" ixy="0.0" ixz="0.0" iyy="0.049443313556" iyz="0.0" izz="0.004095"/>
    </inertial>
  </link>
  <link name="wrist_1_link">
    <visual>
      <origin rpy="0 0 3.141592653589793" xyz="0 0 0"/>
      <geometry>
        <mesh filename="package://ur_description/meshes/ur5e/visual/wrist1.dae"/>
      </geometry>
      <material name="LightGrey">
        <color rgba="0.7 0.7 0.7 1.0"/>
      </material>
    </visual>
    <collision>
      <origin rpy="0 0 3.141592653589793" xyz="0 0 0"/>
      <geometry>
        <mesh filename="package://ur_description/meshes/ur5e/collision/wrist1.stl"/>
      </geometry>
    </collision>
    <inertial>
      <mass value="1.219"/>
      <origin rpy="0 0 0" xyz="0 0 0"/>
      <inertia ixx="0.0025598989761" ixy="0.0" ixz="0.0" iyy="0.0025598989761" iyz="0.0" izz="0.0021942"/>
    </inertial>
  </link>
  <link name="wrist_2_link">
    <visual>
      <origin rpy="0 0 0" xyz="0 0 0"/>
      <geometry>
        <mesh filename="package://ur_description/meshes/ur5e/visual/wrist2.dae"/>
      </geometry>
      <material name="LightGrey">
        <color rgba="0.7 0.7 0.7 1.0"/>
      </material>
    </visual>
    <collision>
      <origin rpy="0 0 0" xyz="0 0 0"/>
      <geometry>
        <mesh filename="package://ur_description/meshes/ur5e/collision/wrist2.stl"/>
      </geometry>
    </collision>
    <inertial>
      <mass value="1.219"/>
      <origin rpy="0 0 0" xyz="0 0 0"/>
      <inertia ixx="0.0025598989761" ixy="0.0" ixz="0.0" iyy="0.0025598989761" iyz="0.0" izz="0.0021942"/>
    </inertial>
  </link>
  <link name="wrist_3_link">
    <visual>
      <origin rpy="0 0 3.141592653589793" xyz="0 0 0"/>
      <geometry>
        <mesh filename="package://ur_description/meshes/ur5e/visual/wrist3.dae"/>
      </geometry>
      <material name="LightGrey">
        <color rgba="0.7 0.7 0.7 1.0"/>
      </material>
    </visual>
    <collision>
      <origin rpy="0 0 3.141592653589793" xyz="0 0 0"/>
      <geometry>
        <mesh filename="package://ur_description/meshes/ur5e/collision/wrist3.stl"/>
      </geometry>
    </collision>
    <inertial>
      <mass value="0.1889"/>
      <origin rpy="0 0 0" xyz="0.0 0.0 -0.0266"/>
      <inertia ixx="9.890410052167e-05" ixy="0.0" ixz="0.0" iyy="9.890410052167e-05" iyz="0.0" izz="0.0001321171875"/>
    </inertial>
  </link>
  <link name="flange"/>
  <link name="tool0"/>
  <!-- joints -->
  <joint name="base_link-base_link_inertia" type="fixed">
    <origin rpy="0 0 0" xyz="0 0 0"/>
    <parent link="base_link"/>
    <child link="base_link_inertia"/>
  </joint>
  <joint name="shoulder_pan_joint" type="revolute">
    <origin rpy="0 0 0" xyz="0 0 0.163"/>
    <axis xyz="0 0 1"/>
    <limit effort="150.0" lower="-6.283185307179586" upper="6.283185307179586" velocity="3.141592653589793"/>
    <safety_controller k_position="20" k_velocity="0" soft_lower_limit="-6.03883822014" soft_upper_limit="6.03883822014"/>
    <dynamics damping="0" friction="0"/>
    <parent link="base_link"/>
    <child link="shoulder_link"/>
  </joint>
  <joint name="shoulder_lift_joint" type="revolute">
    <origin rpy="1.570796326794897 0 0" xyz="0 0.138 0"/>
    <axis xyz="0 0 1"/>
    <limit effort="150.0" lower="-6.283185307179586" upper="6.283185307179586" velocity="3.141592653589793"/>
    <safety_controller k_position="20" k_velocity="0" soft_lower_limit="-6.03883822014" soft_upper_limit="6.03883822014"/>
    <dynamics damping="0" friction="0"/>
    <parent link="shoulder_link"/>
    <child link="upper_arm_link"/>
  </joint>
  <joint name="elbow_joint" type="revolute">
    <origin rpy="0 0 0" xyz="0 -0.131 0.425"/>
    <axis xyz="0 0 1"/>
    <limit effort="150.0" lower="-3.141592653589793" upper="3.141592653589793" velocity="3.141592653589793"/>
    <safety_controller k_position="20" k_velocity="0" soft_lower_limit="-3.05432619099" soft_upper_limit="3.05432619099"/>
    <dynamics damping="0" friction="0"/>
    <parent link="upper_arm_link"/>
    <child link="forearm_link"/>
  </joint>
  <joint name="wrist_1_joint" type="revolute">
    <origin rpy="1.570796326794897 0 0" xyz="0 0 0.392"/>
    <axis xyz="0 0 1"/>
    <limit effort="54.0" lower="-6.283185307179586" upper="6.283185307179586" velocity="6.283185307179586"/>
    <safety_controller k_position="20" k_velocity="0" soft_lower_limit="-6.21337890625" soft_upper_limit="6.21337890625"/>
    <dynamics damping="0" friction="0"/>
    <parent link="forearm_link"/>
    <child link="wrist_1_link"/>
  </joint>
  <joint name="wrist_2_joint" type="revolute">
    <origin rpy="-1.570796326794897 0 0" xyz="0 0.127 0"/>
    <axis xyz="0 0 1"/>
    <limit effort="54.0" lower="-6.283185307179586" upper="6.283185307179586" velocity="6.283185307179586"/>
    <safety_controller k_position="20" k_velocity="0" soft_lower_limit="-6.21337890625" soft_upper_limit="6.21337890625"/>
    <dynamics damping="0" friction="0"/>
    <parent link="wrist_1_link"/>
    <child link="wrist_2_link"/>
  </joint>
  <joint name="wrist_3_joint" type="revolute">
    <origin rpy="1.570796326794897 0 0" xyz="0 -0.1 0"/>
    <axis xyz="0 0 1"/>
    <limit effort="54.0" lower="-6.283185307179586" upper="6.283185307179586" velocity="6.283185307179586"/>
    <safety_controller k_position="20" k_velocity="0" soft_lower_limit="-6.21337890625" soft_upper_limit="6.21337890625"/>
    <dynamics damping="0" friction="0"/>
    <parent link="wrist_2_link"/>
    <child link="wrist_3_link"/>
  </joint>
  <joint name="wrist_3-flange" type="fixed">
    <origin rpy="0 1.570796326794897 0" xyz="0 0 0"/>
    <parent link="wrist_3_link"/>
    <child link="flange"/>
  </joint>
  <joint name="flange-tool0" type="fixed">
    <origin rpy="-1.570796326794897 -1.570796326794897 0" xyz="0 0 0"/>
    <parent link="flange"/>
    <child link="tool0"/>
  </joint>
  <joint name="base-base_link" type="fixed">
    <origin rpy="0 0 0" xyz="0 0 0"/>
    <parent link="base"/>
    <child link="base_link"/>
  </joint>
</robot>